Workbook

Sheet CPYMASTER JOB LOG
A1: MASTER JOB LOG | N1: #VALUE!
A2: Collection Date | B2: Job No. | C2: Customer | D2: Collection Point | E2: Pb Tonnage Kg | F2: CBL LME Value £ | G2: CBL LME % | H2: CBL £ LME | I2: Transport | J2: Customer Invoice Value £ | K2: Customer Invoice No. | L2: CBL Waste Advice Note No. | M2: CBL Date | N2: Total Invoice Value £ | O2: Gross Profit £ | P2: Itinium Invoice No.

Sheet CPYStillages 
A1: West Brom | E1: Basingstoke | I1: Still Exeter
A2: Date | B2: Collected | C2: Dropped off | E2: Date | F2: Collected | G2: Dropped off | I2: Date | J2: Collected | K2: Dropped off
A3: 13.02.24 | B3: 1 | C3: 1 | E3: 27.03.25 | F3: 2 | G3: 2 | I3: 09.07.25 | J3: 1 | K3: 1
A4: 05.02.26 | B4: 3 | C4: 3 | E4: 28.01.06 | F4: 3 | G4: 4

Sheet CPYData Validation
A1: Manufacture
A2: EnerSys Hawker
A3: Espex
A4: Eternity
A5: Exide / GNB
A6: Hawker
A7: Velaris / Ecobat / EDrive
A8: Hoppecke
A9: Juice
A10: Midac
A11: TAB
A12: Triathlon / Sunlight
A13: Other
F15: TAB | J15: Espex | M15: EnerSys / Hawker | P15: Exide / GNB | S15: Midac | V15: Eternity / Juice | Y15: Triathlon / Sunlight | AB15: Velaris / Ecobat / EDrive | AE15: Hoppecke
A16: Battery Voltage | C16: Cell Qty | E16: Manufacture
A17: 12 | C17: 1 | F17: Cell Height | G17: Cell Type | J17: Cell Type | M17: Cell Type | P17: Cell Type | S17: Cell Type | V17: Cell Type | Y17: Cell Type | AB17: Cell Type | AE17: Cell Type
A18: 24 | C18: 2 | H18: Pb content | K18: Pb content | N18: Pb content | Q18: Pb content | T18: Pb content | W18: Pb content | Z18: Pb content | AC18: Pb content | AF18: Pb content
A19: 36 | C19: 3 | G19: "DIN" Standard cells | H19: in kg/cell | J19: "DIN" Standard cells | K19: in kg/cell | M19: "DIN" Standard cells | N19: in kg/cell | P19: "DIN" Standard cells | Q19: in kg/cell | S19: "DIN" Standard cells | T19: in kg/cell | V19: "DIN" Standard cells | W19: in kg/cell | Y19: "DIN" Standard cells | Z19: in kg/cell | AB19: "DIN" Standard cells | AC19: in kg/cell | AE19: "DIN" Standard cells | AF19: in kg/cell
A20: 40 | C20: 4 | E20: All | G20: Unknown | H20: 0 | J20: Unknown | K20: 0 | M20: Unknown | N20: 0 | P20: Unknown | Q20: 0 | S20: Unknown | T20: 0 | V20: Unknown | W20: 0 | Y20: Unknown | Z20: 0 | AB20: Unknown | AC20: 0 | AE20: Unknown | AF20: 0
A21: 48 | C21: 5 | E21: All | G21: Blocs | H21: 0 | J21: Blocs | K21: 0 | M21: Blocs | N21: 0 | P21: Blocs | Q21: 0 | S21: Blocs | T21: 0 | V21: Blocs | W21: 0 | Y21: Blocs | Z21: 0 | AB21: Blocs | AC21: 0 | AE21: Blocs | AF21: 0
A22: 80 | C22: 6 | F22: 282/305mm | G22: 2 EPzS 100 L | H22: 5.7 | J22: 2 IPzS 120 | K22: 6.3 | M22: 2 PzS 120 | N22: 6.5 | P22: 2 EPzS 120 | Q22: 6.5 | S22: 2 MDL 50 | T22: 5.7 | V22: 2 PzS-ET100 | W22: 5.7 | Y22: 2 PzS 100 | Z22: 5.7 | AB22: 2 PzS 100 | AC22: 5.7 | AE22: 2 HPzS 100 | AF22: 5.7
A23: 96 | C23: 7 | G23: 3 EPzS 150 L | H23: 7.7 | J23: 3 IPzS 180 | K23: 8.9 | M23: 3 PzS 180 | N23: 9.2 | P23: 3 EPzS 180 | Q23: 9.2 | S23: 3 MDL 50 | T23: 7.7 | V23: 3 PzS-ET150 | W23: 7.7 | Y23: 3 PzS 150 | Z23: 7.7 | AB23: 3 PzS 150 | AC23: 7.7 | AE23: 3 HPzS 150 | AF23: 7.7
A24: Other | C24: 8 | G24: 4 EPzS 200 L | H24: 9.9 | J24: 4 IPzS 240 | K24: 11.4 | M24: 4 PzS 240 | N24: 11.9 | P24: 4 EPzS 240 | Q24: 11.9 | S24: 4 MDL 50 | T24: 9.9 | V24: 4 PzS-ET200 | W24: 9.9 | Y24: 4 PzS 200 | Z24: 9.9 | AB24: 4 PzS 200 | AC24: 9.9 | AE24: 4 HPzS 200 | AF24: 9.9
A25: Type of Cells PZB/PZS/PZV | C25: 9 | G25: 5 EPzS 250 L | H25: 12.2 | J25: 5 IPzS 300 | K25: 13.9 | M25: 5 PzS 300 | N25: 14.6 | P25: 5 EPzS 300 | Q25: 14.6 | S25: 5 MDL 50 | T25: 12.2 | V25: 5 PzS-ET250 | W25: 12.2 | Y25: 5 PzS 250 | Z25: 12.2 | AB25: 5 PzS 250 | AC25: 12.2 | AE25: 5 HPzS 250 | AF25: 12.2
A26: PzB | C26: 10 | G26: 6 EPzS 300 L | H26: 14.5 | J26: 6 IPzS 360 | K26: 16.6 | M26: 6 PzS 360 | N26: 17.2 | P26: 6 EPzS 360 | Q26: 17.2 | S26: 6 MDL 50 | T26: 14.5 | V26: 6 PzS-ET300 | W26: 14.5 | Y26: 6 PzS 300 | Z26: 14.5 | AB26: 6 PzS 300 | AC26: 14.5 | AE26: 6 HPzS 300 | AF26: 14.5
A27: PzS | C27: 11 | G27: 7 EPzS 350 L | H27: 16.7 | J27: 7 IPzS 420 | K27: 19 | M27: 7 PzS 420 | N27: 19.9 | P27: 7 EPzS 420 | Q27: 19.9 | S27: 7 MDL 50 | T27: 16.7 | V27: 7 PzS-ET350 | W27: 16.7 | Y27: 7 PzS 350 | Z27: 16.7 | AB27: 7 PzS 350 | AC27: 16.7 | AE27: 7 HPzS 350 | AF27: 16.7
A28: PzV | C28: 12 | G28: 8 EPzS 400 L | H28: 19 | J28: 8 IPzS 480 | K28: 21.5 | M28: 8 PzS 480 | N28: 22.6 | P28: 8 EPzS 480 | Q28: 22.6 | S28: 8 MDL 50 | T28: 19 | V28: 8 PzS-ET400 | W28: 19 | Y28: 8 PzS 400 | Z28: 19 | AB28: 8 PzS 400 | AC28: 19 | AE28: 8 HPzS 400 | AF28: 19
A29: Bloc | C29: 13 | G29: 9 EPzS 450 L | H29: 21.3 | J29: 9 IPzS 540 | K29: 24.1 | M29: 9 PzS 540 | N29: 25.2 | P29: 9 EPzS 540 | Q29: 25.2 | S29: 9 MDL 50 | T29: 21.3 | V29: 9 PzS-ET450 | W29: 21.3 | Y29: 9 PzS 450 | Z29: 21.3 | AB29: 9 PzS 450 | AC29: 21.3 | AE29: 9 HPzS 450 | AF29: 21.3
A30: Unknown | C30: 14 | G30: 10 EPzS 500 L | H30: 23.6 | J30: 10 IPzS 600 | K30: 26.7 | M30: 10 PzS 600 | N30: 27.9 | P30: 10 EPzS 600 | Q30: 27.9 | S30: 10 MDL 50 | T30: 23.6 | V30: 10 PzS-ET500 | W30: 23.6 | Y30: 10 PzS 500 | Z30: 23.6 | AB30: 10 PzS 500 | AC30: 23.6 | AE30: 10 HPzS 500 | AF30: 23.6
A31: Confirmation of reciept | C31: 15 | F31: 340/363mm | G31: 2 EPzS 120 L | H31: 6.5 | J31: 2 IPzS 160 | K31: 7.7 | M31: 2 PzS 160 | N31: 8.1 | P31: 2 EPzS 160 | Q31: 8.1 | S31: 2 MDL 60 | T31: 6.5 | V31: 2 PzS-ET120 | W31: 6.5 | Y31: 2 PzS 120 | Z31: 6.5 | AB31: 2 PzS 120 | AC31: 6.5 | AE31: 2 HPzS 120 | AF31: 6.5
A32: a | C32: 16 | G32: 3 EPzS 180 L | H32: 9.2 | J32: 3 IPzS 240 | K32: 11 | M32: 3 PzS 240 | N32: 11.2 | P32: 3 EPzS 240 | Q32: 11.2 | S32: 3 MDL 60 | T32: 9.2 | V32: 3 PzS-ET180 | W32: 9.2 | Y32: 3 PzS 180 | Z32: 9.2 | AB32: 3 PzS 180 | AC32: 9.2 | AE32: 3 HPzS 180 | AF32: 9.2
A33: r | C33: 17 | G33: 4 EPzS 240 L | H33: 11.9 | J33: 4 IPzS 320 | K33: 14 | M33: 4 PzS 320 | N33: 14.6 | P33: 4 EPzS 320 | Q33: 14.6 | S33: 4 MDL 60 | T33: 11.9 | V33: 4 PzS-ET240 | W33: 11.9 | Y33: 4 PzS 240 | Z33: 11.9 | AB33: 4 PzS 240 | AC33: 11.9 | AE33: 4 HPzS 240 | AF33: 11.9
C34: 18 | G34: 5 EPzS 300 L | H34: 14.6 | J34: 5 IPzS 400 | K34: 17.2 | M34: 5 PzS 400 | N34: 17.9 | P34: 5 EPzS 400 | Q34: 17.9 | S34: 5 MDL 60 | T34: 14.6 | V34: 5 PzS-ET300 | W34: 14.6 | Y34: 5 PzS 300 | Z34: 14.6 | AB34: 5 PzS 300 | AC34: 14.6 | AE34: 5 HPzS 300 | AF34: 14.6
A35: Linde Site: | C35: 19 | G35: 6 EPzS 360 L | H35: 17.2 | J35: 6 IPzS 480 | K35: 20.4 | M35: 6 PzS 480 | N35: 21.3 | P35: 6 EPzS 480 | Q35: 21.3 | S35: 6 MDL 60 | T35: 17.2 | V35: 6 PzS-ET360 | W35: 17.2 | Y35: 6 PzS 360 | Z35: 17.2 | AB35: 6 PzS 360 | AC35: 17.2 | AE35: 6 HPzS 360 | AF35: 17.2
A36: Linde South East, Camberley, Surrey, GU15 3BU | C36: 20 | G36: 7 EPzS 420 L | H36: 19.9 | J36: 7 IPzS 560 | K36: 23.4 | M36: 7 PzS 560 | N36: 24.7 | P36: 7 EPzS 560 | Q36: 24.7 | S36: 7 MDL 60 | T36: 19.9 | V36: 7 PzS-ET420 | W36: 19.9 | Y36: 7 PzS 420 | Z36: 19.9 | AB36: 7 PzS 420 | AC36: 19.9 | AE36: 7 HPzS 420 | AF36: 19.9
A37: Linde South, North Road, Bridgend Industrial Estate, Bridgend, Mid Glamorgan, CF31 3SZ | C37: 21 | G37: 8 EPzS 480 L | H37: 22.6 | J37: 8 IPzS 640 | K37: 26.6 | M37: 8 PzS 640 | N37: 28 | P37: 8 EPzS 640 | Q37: 28 | S37: 8 MDL 60 | T37: 22.6 | V37: 8 PzS-ET480 | W37: 22.6 | Y37: 8 PzS 480 | Z37: 22.6 | AB37: 8 PzS 480 | AC37: 22.6 | AE37: 8 HPzS 480 | AF37: 22.6
A38: Linde East, Hoddesdon, Herts, EN11 0DJ | C38: 22 | G38: 9 EPzS 540 L | H38: 25.2 | J38: 9 IPzS 720 | K38: 29.7 | M38: 9 PzS 720 | N38: 31.4 | P38: 9 EPzS 720 | Q38: 31.4 | S38: 9 MDL 60 | T38: 25.2 | V38: 9 PzS-ET540 | W38: 25.2 | Y38: 9 PzS 540 | Z38: 25.2 | AB38: 9 PzS 540 | AC38: 25.2 | AE38: 9 HPzS 540 | AF38: 25.2
A39: Linde Creighton Ltd, Radial Point, Dartmouth Road, West Bromwich, West Midlands. B66 1BG | C39: 23 | G39: 10 EPzS 600 L | H39: 27.9 | J39: 10 IPzS 800 | K39: 33 | M39: 10 PzS 800 | N39: 34.7 | P39: 10 EPzS 800 | Q39: 34.7 | S39: 10 MDL 60 | T39: 27.9 | V39: 10 PzS-ET600 | W39: 27.9 | Y39: 10 PzS 600 | Z39: 27.9 | AB39: 10 PzS 600 | AC39: 27.9 | AE39: 10 HPzS 600 | AF39: 27.9
A40: Linde MH UK Ltd, Winwick Road, Warrington, Cheshire, WA2 8JF | C40: 24 | F40: 402/425mm | G40: 2 EPzS 160 L | H40: 8.1 | J40: 2 IPzS 180 | K40: 8.8 | M40: 2 PzS 180 | N40: 9.1 | P40: 2 EPzS 180 | Q40: 9.1 | S40: 2 MDL 80 | T40: 8.1 | V40: 2 PzS-ET160 | W40: 8.1 | Y40: 2 PzS 160 | Z40: 8.1 | AB40: 2 PzS 160 | AC40: 8.1 | AE40: 2 HPzS 160 | AF40: 8.1
A41: Linde MH UK Ltd, Pioneer Way, Castleford, West Yorkshire, WF10 5QU | C41: 25 | G41: 3 EPzS 240 L | H41: 11.2 | J41: 3 IPzS 270 | K41: 12.6 | M41: 3 PzS 270 | N41: 12.8 | P41: 3 EPzS 270 | Q41: 12.8 | S41: 3 MDL 80 | T41: 11.2 | V41: 3 PzS-ET240 | W41: 11.2 | Y41: 3 PzS 240 | Z41: 11.2 | AB41: 3 PzS 240 | AC41: 11.2 | AE41: 3 HPzS 240 | AF41: 11.2
...

Sheet CPYLME Data 2024-25
A1: LME Data 2024 YTD for Kion Group LME Month prior
A2: https://www.lme.com/en/Metals/Non-ferrous/LME-Lead#Averages
A3: https://www.x-rates.com/average/?from=GBP&to=USD&amount=1&year=2024
A4: Month | B4: $ LME CASH Monthly Average | C4: $ Monthly Average to £ | D4: £ LME CASH Monthly Average | E4: £ LME CASH Monthly Average | F4: Collection Month
A5: 45322 | B5: 2086.3 | C5: 1.270954 | D5: =SUM(Table6[[#This Row],[$ LME CASH Monthly Average]]/Table6[[#This Row],[$ Monthly Average to £]]) -> 1641.5228 | E5: =SUM(Table6[[#This Row],[£ LME CASH Monthly Average]]*10%) -> 164.15228 | F5: =TEXT(IF(DAY(Table6[[#This Row],[Month]]) < 15, DATE(YEAR(Table6[[#This Row],[Month]]), MONTH(Table6[[#This Row],[Month]]), 1) + TIME(0, 0, 0), EOMONTH(Table6[[#This Row],[Month]], 0) + 1), "[$-en-GB]mmm") -> Feb
A6: 45351 | B6: 2083.02 | C6: 1.263235 | D6: =SUM(Table6[[#This Row],[$ LME CASH Monthly Average]]/Table6[[#This Row],[$ Monthly Average to £]]) -> 1648.9568 | E6: =SUM(Table6[[#This Row],[£ LME CASH Monthly Average]]*10%) -> 164.89568 | F6: =TEXT(IF(DAY(Table6[[#This Row],[Month]]) < 15, DATE(YEAR(Table6[[#This Row],[Month]]), MONTH(Table6[[#This Row],[Month]]), 1) + TIME(0, 0, 0), EOMONTH(Table6[[#This Row],[Month]], 0) + 1), "[$-en-GB]mmm") -> Mar
A7: 45382 | B7: 2055.9 | C7: 1.270671 | D7: =SUM(Table6[[#This Row],[$ LME CASH Monthly Average]]/Table6[[#This Row],[$ Monthly Average to £]]) -> 1617.9641 | E7: =SUM(Table6[[#This Row],[£ LME CASH Monthly Average]]*10%) -> 161.79641 | F7: =TEXT(IF(DAY(Table6[[#This Row],[Month]]) < 15, DATE(YEAR(Table6[[#This Row],[Month]]), MONTH(Table6[[#This Row],[Month]]), 1) + TIME(0, 0, 0), EOMONTH(Table6[[#This Row],[Month]], 0) + 1), "[$-en-GB]mmm") -> Apr
A8: 45412 | B8: 2128.74 | C8: 1.251419 | D8: =SUM(Table6[[#This Row],[$ LME CASH Monthly Average]]/Table6[[#This Row],[$ Monthly Average to £]]) -> 1701.061 | E8: =SUM(Table6[[#This Row],[£ LME CASH Monthly Average]]*10%) -> 170.1061 | F8: =TEXT(IF(DAY(Table6[[#This Row],[Month]]) < 15, DATE(YEAR(Table6[[#This Row],[Month]]), MONTH(Table6[[#This Row],[Month]]), 1) + TIME(0, 0, 0), EOMONTH(Table6[[#This Row],[Month]], 0) + 1), "[$-en-GB]mmm") -> May
A9: 45443 | B9: 2220.02 | C9: 1.262745 | D9: =SUM(Table6[[#This Row],[$ LME CASH Monthly Average]]/Table6[[#This Row],[$ Monthly Average to £]]) -> 1758.0905 | E9: =SUM(Table6[[#This Row],[£ LME CASH Monthly Average]]*10%) -> 175.80905 | F9: =TEXT(IF(DAY(Table6[[#This Row],[Month]]) < 15, DATE(YEAR(Table6[[#This Row],[Month]]), MONTH(Table6[[#This Row],[Month]]), 1) + TIME(0, 0, 0), EOMONTH(Table6[[#This Row],[Month]], 0) + 1), "[$-en-GB]mmm") -> Jun
A10: 45473 | B10: 2146.58 | C10: 1.270938 | D10: =SUM(Table6[[#This Row],[$ LME CASH Monthly Average]]/Table6[[#This Row],[$ Monthly Average to £]]) -> 1688.973 | E10: =SUM(Table6[[#This Row],[£ LME CASH Monthly Average]]*10%) -> 168.8973 | F10: =TEXT(IF(DAY(Table6[[#This Row],[Month]]) < 15, DATE(YEAR(Table6[[#This Row],[Month]]), MONTH(Table6[[#This Row],[Month]]), 1) + TIME(0, 0, 0), EOMONTH(Table6[[#This Row],[Month]], 0) + 1), "[$-en-GB]mmm") -> Jul
A11: 45504 | B11: 2146.58 | C11: 1.286336 | D11: =SUM(Table6[[#This Row],[$ LME CASH Monthly Average]]/Table6[[#This Row],[$ Monthly Average to £]]) -> 1668.7553 | E11: =SUM(Table6[[#This Row],[£ LME CASH Monthly Average]]*10%) -> 166.87553 | F11: =TEXT(IF(DAY(Table6[[#This Row],[Month]]) < 15, DATE(YEAR(Table6[[#This Row],[Month]]), MONTH(Table6[[#This Row],[Month]]), 1) + TIME(0, 0, 0), EOMONTH(Table6[[#This Row],[Month]], 0) + 1), "[$-en-GB]mmm") -> Aug
A12: 45535 | B12: 2001.21 | C12: 1.293435 | D12: =SUM(Table6[[#This Row],[$ LME CASH Monthly Average]]/Table6[[#This Row],[$ Monthly Average to £]]) -> 1547.2057 | E12: =SUM(Table6[[#This Row],[£ LME CASH Monthly Average]]*10%) -> 154.72057 | F12: =TEXT(IF(DAY(Table6[[#This Row],[Month]]) < 15, DATE(YEAR(Table6[[#This Row],[Month]]), MONTH(Table6[[#This Row],[Month]]), 1) + TIME(0, 0, 0), EOMONTH(Table6[[#This Row],[Month]], 0) + 1), "[$-en-GB]mmm") -> Sep
A13: 45565 | B13: 2006.1 | C13: 1.321129 | D13: =SUM(Table6[[#This Row],[$ LME CASH Monthly Average]]/Table6[[#This Row],[$ Monthly Average to £]]) -> 1518.474 | E13: =SUM(Table6[[#This Row],[£ LME CASH Monthly Average]]*10%) -> 151.8474 | F13: =TEXT(IF(DAY(Table6[[#This Row],[Month]]) < 15, DATE(YEAR(Table6[[#This Row],[Month]]), MONTH(Table6[[#This Row],[Month]]), 1) + TIME(0, 0, 0), EOMONTH(Table6[[#This Row],[Month]], 0) + 1), "[$-en-GB]mmm") -> Oct
A14: 45596 | B14: 2034.52 | C14: 1.305953 | D14: =SUM(Table6[[#This Row],[$ LME CASH Monthly Average]]/Table6[[#This Row],[$ Monthly Average to £]]) -> 1557.8815 | E14: =SUM(Table6[[#This Row],[£ LME CASH Monthly Average]]*10%) -> 155.78815 | F14: =TEXT(IF(DAY(Table6[[#This Row],[Month]]) < 15, DATE(YEAR(Table6[[#This Row],[Month]]), MONTH(Table6[[#This Row],[Month]]), 1) + TIME(0, 0, 0), EOMONTH(Table6[[#This Row],[Month]], 0) + 1), "[$-en-GB]mmm") -> Nov
A15: 45626 | B15: 1987.17 | C15: 1.275405 | D15: =SUM(Table6[[#This Row],[$ LME CASH Monthly Average]]/Table6[[#This Row],[$ Monthly Average to £]]) -> 1558.0698 | E15: =SUM(Table6[[#This Row],[£ LME CASH Monthly Average]]*10%) -> 155.80698 | F15: =TEXT(IF(DAY(Table6[[#This Row],[Month]]) < 15, DATE(YEAR(Table6[[#This Row],[Month]]), MONTH(Table6[[#This Row],[Month]]), 1) + TIME(0, 0, 0), EOMONTH(Table6[[#This Row],[Month]], 0) + 1), "[$-en-GB]mmm") -> Dec
A16: 45657 | B16: 1993.03 | C16: 1.26064 | D16: =SUM(Table6[[#This Row],[$ LME CASH Monthly Average]]/Table6[[#This Row],[$ Monthly Average to £]]) -> 1580.9668 | E16: =SUM(Table6[[#This Row],[£ LME CASH Monthly Average]]*10%) -> 158.09668 | F16: =TEXT(IF(DAY(Table6[[#This Row],[Month]]) < 15, DATE(YEAR(Table6[[#This Row],[Month]]), MONTH(Table6[[#This Row],[Month]]), 1) + TIME(0, 0, 0), EOMONTH(Table6[[#This Row],[Month]], 0) + 1), "[$-en-GB]mmm") -> Jan
... A26: 45961 | B26: 1967.15 | C26: 1.337238 | D26: =SUM(Table6[[#This Row],[$ LME CASH Monthly Average]]/Table6[[#This Row],[$ Monthly Average to £]]) -> 1471.0545 | E26: =SUM(Table6[[#This Row],[£ LME CASH Monthly Average]]*10%) -> 147.10545 | F26: =TEXT(IF(DAY(Table6[[#This Row],[Month]]) < 15, DATE(YEAR(Table6[[#This Row],[Month]]), MONTH(Table6[[#This Row],[Month]]), 1) + TIME(0, 0, 0), EOMONTH(Table6[[#This Row],[Month]], 0) + 1), "[$-en-GB]mmm") -> Nov
A27: 45991 | B27: 2000.6 | C27: 1.314343 | D27: =SUM(Table6[[#This Row],[$ LME CASH Monthly Average]]/Table6[[#This Row],[$ Monthly Average to £]]) -> 1522.1293 | E27: =SUM(Table6[[#This Row],[£ LME CASH Monthly Average]]*10%) -> 152.21293 | F27: Dec
A28: 46022 | B28: 1941.19 | C28: 1.338708 | D28: =SUM(Table6[[#This Row],[$ LME CASH Monthly Average]]/Table6[[#This Row],[$ Monthly Average to £]]) -> 1450.0474 | E28: =SUM(Table6[[#This Row],[£ LME CASH Monthly Average]]*10%) -> 145.00474 | F28: =TEXT(IF(DAY(Table6[[#This Row],[Month]]) < 15, DATE(YEAR(Table6[[#This Row],[Month]]), MONTH(Table6[[#This Row],[Month]]), 1) + TIME(0, 0, 0), EOMONTH(Table6[[#This Row],[Month]], 0) + 1), "[$-en-GB]mmm") -> Jan
A29: 46053 | B29: 1996.81 | C29: 1.351078 | D29: =SUM(Table6[[#This Row],[$ LME CASH Monthly Average]]/Table6[[#This Row],[$ Monthly Average to £]]) -> 1477.9384 | E29: =SUM(Table6[[#This Row],[£ LME CASH Monthly Average]]*10%) -> 147.79384 | F29: =TEXT(IF(DAY(Table6[[#This Row],[Month]]) < 15, DATE(YEAR(Table6[[#This Row],[Month]]), MONTH(Table6[[#This Row],[Month]]), 1) + TIME(0, 0, 0), EOMONTH(Table6[[#This Row],[Month]], 0) + 1), "[$-en-GB]mmm") -> Feb
A30: 46081 | B30: 1915.03 | C30: 1.358606 | D30: =SUM(Table6[[#This Row],[$ LME CASH Monthly Average]]/Table6[[#This Row],[$ Monthly Average to £]]) -> 1409.5551 | E30: =SUM(Table6[[#This Row],[£ LME CASH Monthly Average]]*10%) -> 140.95551 | F30: =TEXT(IF(DAY(Table6[[#This Row],[Month]]) < 15, DATE(YEAR(Table6[[#This Row],[Month]]), MONTH(Table6[[#This Row],[Month]]), 1) + TIME(0, 0, 0), EOMONTH(Table6[[#This Row],[Month]], 0) + 1), "[$-en-GB]mmm") -> Mar
A31: 46112 | D31: =SUM(Table6[[#This Row],[$ LME CASH Monthly Average]]/Table6[[#This Row],[$ Monthly Average to £]]) -> #DIV/0! | E31: =SUM(Table6[[#This Row],[£ LME CASH Monthly Average]]*10%) -> #DIV/0! | F31: =TEXT(IF(DAY(Table6[[#This Row],[Month]]) < 15, DATE(YEAR(Table6[[#This Row],[Month]]), MONTH(Table6[[#This Row],[Month]]), 1) + TIME(0, 0, 0), EOMONTH(Table6[[#This Row],[Month]], 0) + 1), "[$-en-GB]mmm") -> Apr
A32: 46142 | D32: =SUM(Table6[[#This Row],[$ LME CASH Monthly Average]]/Table6[[#This Row],[$ Monthly Average to £]]) -> #DIV/0! | E32: =SUM(Table6[[#This Row],[£ LME CASH Monthly Average]]*10%) -> #DIV/0! | F32: =TEXT(IF(DAY(Table6[[#This Row],[Month]]) < 15, DATE(YEAR(Table6[[#This Row],[Month]]), MONTH(Table6[[#This Row],[Month]]), 1) + TIME(0, 0, 0), EOMONTH(Table6[[#This Row],[Month]], 0) + 1), "[$-en-GB]mmm") -> May
A33: 46173 | D33: =SUM(Table6[[#This Row],[$ LME CASH Monthly Average]]/Table6[[#This Row],[$ Monthly Average to £]]) -> #DIV/0! | E33: =SUM(Table6[[#This Row],[£ LME CASH Monthly Average]]*10%) -> #DIV/0! | F33: =TEXT(IF(DAY(Table6[[#This Row],[Month]]) < 15, DATE(YEAR(Table6[[#This Row],[Month]]), MONTH(Table6[[#This Row],[Month]]), 1) + TIME(0, 0, 0), EOMONTH(Table6[[#This Row],[Month]], 0) + 1), "[$-en-GB]mmm") -> Jun
A34: 46203 | D34: =SUM(Table6[[#This Row],[$ LME CASH Monthly Average]]/Table6[[#This Row],[$ Monthly Average to £]]) -> #DIV/0! | E34: =SUM(Table6[[#This Row],[£ LME CASH Monthly Average]]*10%) -> #DIV/0! | F34: =TEXT(IF(DAY(Table6[[#This Row],[Month]]) < 15, DATE(YEAR(Table6[[#This Row],[Month]]), MONTH(Table6[[#This Row],[Month]]), 1) + TIME(0, 0, 0), EOMONTH(Table6[[#This Row],[Month]], 0) + 1), "[$-en-GB]mmm") -> Jul
A35: 46234 | D35: =SUM(Table6[[#This Row],[$ LME CASH Monthly Average]]/Table6[[#This Row],[$ Monthly Average to £]]) -> #DIV/0! | E35: =SUM(Table6[[#This Row],[£ LME CASH Monthly Average]]*10%) -> #DIV/0! | F35: =TEXT(IF(DAY(Table6[[#This Row],[Month]]) < 15, DATE(YEAR(Table6[[#This Row],[Month]]), MONTH(Table6[[#This Row],[Month]]), 1) + TIME(0, 0, 0), EOMONTH(Table6[[#This Row],[Month]], 0) + 1), "[$-en-GB]mmm") -> Aug
A36: 46265 | D36: =SUM(Table6[[#This Row],[$ LME CASH Monthly Average]]/Table6[[#This Row],[$ Monthly Average to £]]) -> #DIV/0! | E36: =SUM(Table6[[#This Row],[£ LME CASH Monthly Average]]*10%) -> #DIV/0! | F36: =TEXT(IF(DAY(Table6[[#This Row],[Month]]) < 15, DATE(YEAR(Table6[[#This Row],[Month]]), MONTH(Table6[[#This Row],[Month]]), 1) + TIME(0, 0, 0), EOMONTH(Table6[[#This Row],[Month]], 0) + 1), "[$-en-GB]mmm") -> Sep
A37: 46295 | D37: =SUM(Table6[[#This Row],[$ LME CASH Monthly Average]]/Table6[[#This Row],[$ Monthly Average to £]]) -> #DIV/0! | E37: =SUM(Table6[[#This Row],[£ LME CASH Monthly Average]]*10%) -> #DIV/0! | F37: =TEXT(IF(DAY(Table6[[#This Row],[Month]]) < 15, DATE(YEAR(Table6[[#This Row],[Month]]), MONTH(Table6[[#This Row],[Month]]), 1) + TIME(0, 0, 0), EOMONTH(Table6[[#This Row],[Month]], 0) + 1), "[$-en-GB]mmm") -> Oct
A38: 46326 | D38: =SUM(Table6[[#This Row],[$ LME CASH Monthly Average]]/Table6[[#This Row],[$ Monthly Average to £]]) -> #DIV/0! | E38: =SUM(Table6[[#This Row],[£ LME CASH Monthly Average]]*10%) -> #DIV/0! | F38: =TEXT(IF(DAY(Table6[[#This Row],[Month]]) < 15, DATE(YEAR(Table6[[#This Row],[Month]]), MONTH(Table6[[#This Row],[Month]]), 1) + TIME(0, 0, 0), EOMONTH(Table6[[#This Row],[Month]], 0) + 1), "[$-en-GB]mmm") -> Nov
A39: 46356 | D39: =SUM(Table6[[#This Row],[$ LME CASH Monthly Average]]/Table6[[#This Row],[$ Monthly Average to £]]) -> #DIV/0! | E39: =SUM(Table6[[#This Row],[£ LME CASH Monthly Average]]*10%) -> #DIV/0! | F39: =TEXT(IF(DAY(Table6[[#This Row],[Month]]) < 15, DATE(YEAR(Table6[[#This Row],[Month]]), MONTH(Table6[[#This Row],[Month]]), 1) + TIME(0, 0, 0), EOMONTH(Table6[[#This Row],[Month]], 0) + 1), "[$-en-GB]mmm") -> Dec
A40: 46387 | D40: =SUM(Table6[[#This Row],[$ LME CASH Monthly Average]]/Table6[[#This Row],[$ Monthly Average to £]]) -> #DIV/0! | E40: =SUM(Table6[[#This Row],[£ LME CASH Monthly Average]]*10%) -> #DIV/0! | F40: =TEXT(IF(DAY(Table6[[#This Row],[Month]]) < 15, DATE(YEAR(Table6[[#This Row],[Month]]), MONTH(Table6[[#This Row],[Month]]), 1) + TIME(0, 0, 0), EOMONTH(Table6[[#This Row],[Month]], 0) + 1), "[$-en-GB]mmm") -> Jan

Sheet CPYPbTraction_Auto_Split_25
E2: #VALUE!
A3: Kion volume as of 01/01/2025 - 31/12/2025
A5: Collection Point | B5: Sum of Traction Pb Kg | C5: Sum of Automotive Pb Kg | D5: Grand Total Pb Kg
A6: Andover | B6: 9475.2
A7: Basingstoke | B7: 48547.4 | C7: 1353.3
A8: Bridgend | B8: 213832.5
A9: Castleford | B9: 103311.4
A10: East Kilbride | B10: 32834.9 | C10: 885.95
A11: Exeter | B11: 260202.6 | C11: 471
A12: Newton Aycliffe | B12: 114207.6
A13: Swanley | B13: 7905.6
A14: Warrington | B14: 15438.8
A15: Wellingborough | B15: 169322.2
A16: West Bromwich | B16: 236542 | C16: 1123
D18: 1215453

Sheet CPYKION_COLLECTION SHEET
A1: #VALUE! | C1: Redundant Battery Collection Note Job No. | G1: collections@itinium.co.uk | H1: #VALUE!
A2: Date: | D2: Collection point:
A3: Pallet No. | B3: Asset No. | C3: Battery Serial Number | D3: Manufacture | E3: If Loose Cells - Qty | F3: If Complete Battery - Voltage | G3: Type of Cells PZB/PZS/PZV/Blocs etc. | H3: Notes
D27: This document is the confirmation and agreement for Itinium to remove the above redundant batteries for further inspection.
A28: Collection Driver | G28: Site Contact Name
A29: Date | G29: Date
A31: Signature | G31: Signature
A34: #VALUE! | C34: Redundant Battery Collection Note Job No. | G34: collections@itinium.co.uk | H34: #VALUE!
A35: Date: | B35: 45707 | D35: Collection point:
A36: Pallet No. | B36: Asset No. | C36: Battery Serial Number | D36: Manufacture | E36: If Loose Cells - Qty | F36: If Complete Battery - Voltage | G36: Type of Cells PZB/PZS/PZV/Blocs etc. | H36: Notes
D60: This document is the confirmation and agreement for Itinium to remove the above redundant batteries for further inspection.
A61: Collection Driver | G61: Site Contact Name
A62: Date | G62: Date
A64: Signature | G64: Signature

Sheet CPYKION Collection Data
A1: KION Group Collection Data from May 2024 - YTD
A3: Collection Date | B3: Job No. | C3: Kion Partner | D3: Collection Point | E3: Traction Pb Tonnage Kg | F3: Automotive Pb Tonnage Kg | G3: LME Value £ | H3: Transport | I3: Nett Invoice Value £ | J3: Kion Ptnr Invoice No. | K3: inv Recieved | L3: Due Date | M3: Date Paid | N3: Days to pay | O3: Comments

Sheet CPYKION_MASTER
A1: #VALUE! | C1: Redundant Battery Collection Note Job No. | G1: collections@itinium.co.uk | H1: #VALUE! | M1: #VALUE!
A2: Collection Date: | D2: Collection point:
A3: Pallet No. | B3: Asset No. | C3: Battery Serial Number | D3: Manufacture | E3: If Loose Cells - Qty | F3: If Complete Battery - Voltage | G3: Type of Cells PZB/PZS/PZV/Blocs etc. | H3: Notes | I3: →Intinium to Complete← | J3: Confirmation of receipt | K3: Pb Content Kg | L3: £ Value | M3: Notes
K4: =VLOOKUP(G4,'CPYData Validation'!G:H,2,FALSE)*Table31018122[[#This Row],[If Complete Battery - Voltage]]/2 -> #N/A | L4: =Table41119123[[#This Row],[Pb Content Kg]]*K1/1000 -> #N/A
K5: =VLOOKUP(G5,'CPYData Validation'!G:H,2,FALSE)*Table31018122[[#This Row],[If Complete Battery - Voltage]]/2 -> #N/A | L5: =Table41119123[[#This Row],[Pb Content Kg]]*K1/1000 -> #N/A
K6: =VLOOKUP(G6,'CPYData Validation'!G:H,2,FALSE)*Table31018122[[#This Row],[If Complete Battery - Voltage]]/2 -> #N/A | L6: =Table41119123[[#This Row],[Pb Content Kg]]*K1/1000 -> #N/A
K7: =VLOOKUP(G7,'CPYData Validation'!G:H,2,FALSE)*Table31018122[[#This Row],[If Complete Battery - Voltage]]/2 -> #N/A | L7: =Table41119123[[#This Row],[Pb Content Kg]]*K1/1000 -> #N/A
K8: =VLOOKUP(G8,'CPYData Validation'!G:H,2,FALSE)*Table31018122[[#This Row],[If Complete Battery - Voltage]]/2 -> #N/A | L8: =Table41119123[[#This Row],[Pb Content Kg]]*K1/1000 -> #N/A
K9: =VLOOKUP(G9,'CPYData Validation'!G:H,2,FALSE)*Table31018122[[#This Row],[If Complete Battery - Voltage]]/2 -> #N/A | L9: =Table41119123[[#This Row],[Pb Content Kg]]*K1/1000 -> #N/A
K10: =VLOOKUP(G10,'CPYData Validation'!G:H,2,FALSE)*Table31018122[[#This Row],[If Complete Battery - Voltage]]/2 -> #N/A | L10: =Table41119123[[#This Row],[Pb Content Kg]]*K1/1000 -> #N/A
K11: =VLOOKUP(G11,'CPYData Validation'!G:H,2,FALSE)*Table31018122[[#This Row],[If Complete Battery - Voltage]]/2 -> #N/A | L11: =Table41119123[[#This Row],[Pb Content Kg]]*K1/1000 -> #N/A
K12: =VLOOKUP(G12,'CPYData Validation'!G:H,2,FALSE)*Table31018122[[#This Row],[If Complete Battery - Voltage]]/2 -> #N/A | L12: =Table41119123[[#This Row],[Pb Content Kg]]*K1/1000 -> #N/A
K13: =VLOOKUP(G13,'CPYData Validation'!G:H,2,FALSE)*Table31018122[[#This Row],[If Complete Battery - Voltage]]/2 -> #N/A | L13: =Table41119123[[#This Row],[Pb Content Kg]]*K1/1000 -> #N/A
K14: =VLOOKUP(G14,'CPYData Validation'!G:H,2,FALSE)*Table31018122[[#This Row],[If Complete Battery - Voltage]]/2 -> #N/A | L14: =Table41119123[[#This Row],[Pb Content Kg]]*K1/1000 -> #N/A
K15: =VLOOKUP(G15,'CPYData Validation'!G:H,2,FALSE)*Table31018122[[#This Row],[If Complete Battery - Voltage]]/2 -> #N/A | L15: =Table41119123[[#This Row],[Pb Content Kg]]*K1/1000 -> #N/A
K16: =VLOOKUP(G16,'CPYData Validation'!G:H,2,FALSE)*Table31018122[[#This Row],[If Complete Battery - Voltage]]/2 -> #N/A | L16: =Table41119123[[#This Row],[Pb Content Kg]]*K1/1000 -> #N/A
K17: =VLOOKUP(G17,'CPYData Validation'!G:H,2,FALSE)*Table31018122[[#This Row],[If Complete Battery - Voltage]]/2 -> #N/A | L17: =Table41119123[[#This Row],[Pb Content Kg]]*K1/1000 -> #N/A
K18: =VLOOKUP(G18,'CPYData Validation'!G:H,2,FALSE)*Table31018122[[#This Row],[If Complete Battery - Voltage]]/2 -> #N/A | L18: =Table41119123[[#This Row],[Pb Content Kg]]*K1/1000 -> #N/A
K19: =VLOOKUP(G19,'CPYData Validation'!G:H,2,FALSE)*Table31018122[[#This Row],[If Complete Battery - Voltage]]/2 -> #N/A | L19: =Table41119123[[#This Row],[Pb Content Kg]]*K1/1000 -> #N/A
K20: =VLOOKUP(G20,'CPYData Validation'!G:H,2,FALSE)*Table31018122[[#This Row],[If Complete Battery - Voltage]]/2 -> #N/A | L20: =Table41119123[[#This Row],[Pb Content Kg]]*K1/1000 -> #N/A
K21: =VLOOKUP(G21,'CPYData Validation'!G:H,2,FALSE)*Table31018122[[#This Row],[If Complete Battery - Voltage]]/2 -> #N/A | L21: =Table41119123[[#This Row],[Pb Content Kg]]*K1/1000 -> #N/A
K22: =VLOOKUP(G22,'CPYData Validation'!G:H,2,FALSE)*Table31018122[[#This Row],[If Complete Battery - Voltage]]/2 -> #N/A | L22: =Table41119123[[#This Row],[Pb Content Kg]]*K1/1000 -> #N/A
K23: =VLOOKUP(G23,'CPYData Validation'!G:H,2,FALSE)*Table31018122[[#This Row],[If Complete Battery - Voltage]]/2 -> #N/A | L23: =Table41119123[[#This Row],[Pb Content Kg]]*K1/1000 -> #N/A
K24: =VLOOKUP(G24,'CPYData Validation'!G:H,2,FALSE)*Table31018122[[#This Row],[If Complete Battery - Voltage]]/2 -> #N/A | L24: =Table41119123[[#This Row],[Pb Content Kg]]*K1/1000 -> #N/A
K25: =VLOOKUP(G25,'CPYData Validation'!G:H,2,FALSE)*Table31018122[[#This Row],[If Complete Battery - Voltage]]/2 -> #N/A | L25: =Table41119123[[#This Row],[Pb Content Kg]]*K1/1000 -> #N/A
K26: =VLOOKUP(G26,'CPYData Validation'!G:H,2,FALSE)*Table31018122[[#This Row],[If Complete Battery - Voltage]]/2 -> #N/A | L26: =Table41119123[[#This Row],[Pb Content Kg]]*K1/1000 -> #N/A
K27: =VLOOKUP(G27,'CPYData Validation'!G:H,2,FALSE)*Table31018122[[#This Row],[If Complete Battery - Voltage]]/2 -> #N/A | L27: =Table41119123[[#This Row],[Pb Content Kg]]*K1/1000 -> #N/A
K28: =VLOOKUP(G28,'CPYData Validation'!G:H,2,FALSE)*Table31018122[[#This Row],[If Complete Battery - Voltage]]/2 -> #N/A | L28: =Table41119123[[#This Row],[Pb Content Kg]]*K1/1000 -> #N/A
K29: =VLOOKUP(G29,'CPYData Validation'!G:H,2,FALSE)*Table31018122[[#This Row],[If Complete Battery - Voltage]]/2 -> #N/A | L29: =Table41119123[[#This Row],[Pb Content Kg]]*K1/1000 -> #N/A
K30: =VLOOKUP(G30,'CPYData Validation'!G:H,2,FALSE)*Table31018122[[#This Row],[If Complete Battery - Voltage]]/2 -> #N/A | L30: =Table41119123[[#This Row],[Pb Content Kg]]*K1/1000 -> #N/A
K31: =VLOOKUP(G31,'CPYData Validation'!G:H,2,FALSE)*Table31018122[[#This Row],[If Complete Battery - Voltage]]/2 -> #N/A | L31: =Table41119123[[#This Row],[Pb Content Kg]]*K1/1000 -> #N/A
K32: =VLOOKUP(G32,'CPYData Validation'!G:H,2,FALSE)*Table31018122[[#This Row],[If Complete Battery - Voltage]]/2 -> #N/A | L32: =Table41119123[[#This Row],[Pb Content Kg]]*K1/1000 -> #N/A
K33: =VLOOKUP(G33,'CPYData Validation'!G:H,2,FALSE)*Table31018122[[#This Row],[If Complete Battery - Voltage]]/2 -> #N/A | L33: =Table41119123[[#This Row],[Pb Content Kg]]*K1/1000 -> #N/A
D34: This document is the confirmation and agreement for Itinium to remove the above redundant batteries for further inspection.
A35: Collection Driver | G35: Site Contact Name
A36: Date | G36: Date
A38: Signature | G38: Signature
J39: Transport
J40: Total Invoice Value | M40: =SUM(L4:L39)-M39 -> #N/A
J41: Invoice Number

Sheet CPYC01261152
A1: #VALUE! | C1: Redundant Battery Collection Note Job No.01261152 | G1: collections@itinium.co.uk | H1: #VALUE! | K1: 100 | M1: #VALUE!
A2: Collection Date: | B2: 46058 | D2: Collection point: | E2: Linde Creighton Ltd, Radial Point, Dartmouth Road, West Bromwich, West Midlands. B66 1BG
A3: Pallet No. | B3: Asset No. | C3: Battery Serial Number | D3: Manufacture | E3: If Loose Cells - Qty | F3: If Complete Battery - Voltage | G3: Type of Cells PZB/PZS/PZV/Blocs etc. | H3: Notes | I3: →Intinium to Complete← | J3: Confirmation of receipt | K3: Pb Content Kg | L3: £ Value | M3: Notes
A4: 1 | B4: LG61/748 | C4: L006176 | D4: GNB | F4: 48 | G4: 4PzS460 | H4: 700KG | J4: a | K4: =VLOOKUP(G4,'CPYData Validation'!G:H,2,FALSE)*Table31018122324[[#This Row],[If Complete Battery - Voltage]]/2 -> #N/A | L4: =Table41119123325[[#This Row],[Pb Content Kg]]*K1/1000 -> #N/A
A5: 2 | B5: LG61/749 | C5: LW001933 | D5: GNB | F5: 24 | G5: 3PzS345 | H5: 280KG | J5: a | K5: =VLOOKUP(G5,'CPYData Validation'!G:H,2,FALSE)*Table31018122324[[#This Row],[If Complete Battery - Voltage]]/2 -> #N/A | L5: =Table41119123325[[#This Row],[Pb Content Kg]]*K1/1000 -> #N/A
A6: 2 | B6: LG61/750 | C6: L006178 | D6: LINDE | F6: 24 | G6: 3PzS375 | H6: 296KG | J6: a | K6: =VLOOKUP(G6,'CPYData Validation'!G:H,2,FALSE)*Table31018122324[[#This Row],[If Complete Battery - Voltage]]/2 -> #N/A | L6: =Table41119123325[[#This Row],[Pb Content Kg]]*K1/1000 -> #N/A
A7: 2 | B7: LG61/751 | C7: L006177 | D7: GNB | F7: 24 | G7: 3PzS375 | H7: 296KG | J7: a | K7: =VLOOKUP(G7,'CPYData Validation'!G:H,2,FALSE)*Table31018122324[[#This Row],[If Complete Battery - Voltage]]/2 -> #N/A | L7: =Table41119123325[[#This Row],[Pb Content Kg]]*K1/1000 -> #N/A
A8: 2 | B8: LG61/752 | C8: LW000501 | D8: LINDE | F8: 24 | G8: 3PzS375 | H8: 296KG | J8: a | K8: =VLOOKUP(G8,'CPYData Validation'!G:H,2,FALSE)*Table31018122324[[#This Row],[If Complete Battery - Voltage]]/2 -> #N/A | L8: =Table41119123325[[#This Row],[Pb Content Kg]]*K1/1000 -> #N/A
A9: 3 | B9: LG61/753 | C9: L002404 | D9: GNB | F9: 24 | G9: 3PzS345 | H9: 280KG | J9: a | K9: =VLOOKUP(G9,'CPYData Validation'!G:H,2,FALSE)*Table31018122324[[#This Row],[If Complete Battery - Voltage]]/2 -> #N/A | L9: =Table41119123325[[#This Row],[Pb Content Kg]]*K1/1000 -> #N/A
A10: 3 | B10: LG61/754 | C10: L006180 | D10: GNB | F10: 24 | G10: 3PzS375 | H10: 296KG | J10: a | K10: =VLOOKUP(G10,'CPYData Validation'!G:H,2,FALSE)*Table31018122324[[#This Row],[If Complete Battery - Voltage]]/2 -> #N/A | L10: =Table41119123325[[#This Row],[Pb Content Kg]]*K1/1000 -> #N/A
A11: 3 | B11: LG61/755 | C11: L006181 | D11: GNB | F11: 24 | G11: 4PzS500 | H11: 388KG | J11: a | K11: =VLOOKUP(G11,'CPYData Validation'!G:H,2,FALSE)*Table31018122324[[#This Row],[If Complete Battery - Voltage]]/2 -> #N/A | L11: =Table41119123325[[#This Row],[Pb Content Kg]]*K1/1000 -> #N/A
A12: 3 | B12: LG61/756 | C12: 6013202 | D12: GNB | F12: 24 | G12: 2PzB200 | H12: 190KG PLEASE CHECK CELL SIZE | J12: a | K12: =VLOOKUP(G12,'CPYData Validation'!G:H,2,FALSE)*Table31018122324[[#This Row],[If Complete Battery - Voltage]]/2 -> #N/A | L12: =Table41119123325[[#This Row],[Pb Content Kg]]*K1/1000 -> #N/A | M12: Listed as 3EpzS200 confirmed as 2PzB200
A13: 4 | B13: LG61/757 | C13: L005563 | D13: MIDAC | F13: 24 | G13: 3PzS375 | H13: 296KG | J13: a | K13: =VLOOKUP(G13,'CPYData Validation'!G:H,2,FALSE)*Table31018122324[[#This Row],[If Complete Battery - Voltage]]/2 -> #N/A | L13: =Table41119123325[[#This Row],[Pb Content Kg]]*K1/1000 -> #N/A
A14: 4 | B14: LG61/758 | C14: L006179 | D14: MIDAC | F14: 24 | G14: 3PzS375 | H14: 296KG | J14: a | K14: =VLOOKUP(G14,'CPYData Validation'!G:H,2,FALSE)*Table31018122324[[#This Row],[If Complete Battery - Voltage]]/2 -> #N/A | L14: =Table41119123325[[#This Row],[Pb Content Kg]]*K1/1000 -> #N/A
A15: 4 | B15: LG61/759 | C15: 601945 | D15: GNB | F15: 24 | G15: 3PzS375 | H15: 296KG | J15: a | K15: =VLOOKUP(G15,'CPYData Validation'!G:H,2,FALSE)*Table31018122324[[#This Row],[If Complete Battery - Voltage]]/2 -> #N/A | L15: =Table41119123325[[#This Row],[Pb Content Kg]]*K1/1000 -> #N/A
A16: 4 | B16: LG61/760 | C16: L003906 | D16: LINDE | F16: 24 | G16: 3PzS375 | H16: 296KG IN CENTRAL 4 PALLETS | J16: a | K16: =VLOOKUP(G16,'CPYData Validation'!G:H,2,FALSE)*Table31018122324[[#This Row],[If Complete Battery - Voltage]]/2 -> #N/A | L16: =Table41119123325[[#This Row],[Pb Content Kg]]*K1/1000 -> #N/A
A17: 5 | B17: LG61/761 | C17: l005756 | D17: HAWKER | F17: 48 | G17: 5PZS775 | H17: 1170KG | J17: a | K17: =VLOOKUP(G17,'CPYData Validation'!G:H,2,FALSE)*Table31018122324[[#This Row],[If Complete Battery - Voltage]]/2 -> #N/A | L17: =Table41119123325[[#This Row],[Pb Content Kg]]*K1/1000 -> #N/A
A18: 6 | B18: LG61/762 | C18: L005761 | D18: HAWKER | F18: 48 | G18: 5PZS775 | H18: 1170KG | J18: a | K18: =VLOOKUP(G18,'CPYData Validation'!G:H,2,FALSE)*Table31018122324[[#This Row],[If Complete Battery - Voltage]]/2 -> #N/A | L18: =Table41119123325[[#This Row],[Pb Content Kg]]*K1/1000 -> #N/A
A19: 7 | B19: LG61/763 | C19: L005745 | D19: GNB | F19: 24 | G19: 4PzS500 | H19: 388KG | J19: a | K19: =VLOOKUP(G19,'CPYData Validation'!G:H,2,FALSE)*Table31018122324[[#This Row],[If Complete Battery - Voltage]]/2 -> #N/A | L19: =Table41119123325[[#This Row],[Pb Content Kg]]*K1/1000 -> #N/A
A20: 7 | B20: LG61/764 | C20: L005744 | D20: GNB | F20: 48 | G20: 5PZS775 | H20: 1170KG | J20: a | K20: =VLOOKUP(G20,'CPYData Validation'!G:H,2,FALSE)*Table31018122324[[#This Row],[If Complete Battery - Voltage]]/2 -> #N/A | L20: =Table41119123325[[#This Row],[Pb Content Kg]]*K1/1000 -> #N/A
A21: 8 | B21: LG61/765 | C21: L005743 | D21: HAWKER | F21: 48 | G21: 5PZS775 | H21: 1170KG | J21: a | K21: =VLOOKUP(G21,'CPYData Validation'!G:H,2,FALSE)*Table31018122324[[#This Row],[If Complete Battery - Voltage]]/2 -> #N/A | L21: =Table41119123325[[#This Row],[Pb Content Kg]]*K1/1000 -> #N/A
A22: 8 | B22: LG61/766 | C22: L005742 | D22: GNB | F22: 24 | G22: 4PzS500 | H22: 388KG | J22: a | K22: =VLOOKUP(G22,'CPYData Validation'!G:H,2,FALSE)*Table31018122324[[#This Row],[If Complete Battery - Voltage]]/2 -> #N/A | L22: =Table41119123325[[#This Row],[Pb Content Kg]]*K1/1000 -> #N/A
A23: 9 | B23: LG61/767 | C23: L005749 | D23: GNB | F23: 48 | G23: 5PZS775 | H23: 1170KG | J23: a | K23: =VLOOKUP(G23,'CPYData Validation'!G:H,2,FALSE)*Table31018122324[[#This Row],[If Complete Battery - Voltage]]/2 -> #N/A | L23: =Table41119123325[[#This Row],[Pb Content Kg]]*K1/1000 -> #N/A
A24: 9 | B24: LG61/768 | C24: L005750 | D24: GNB | F24: 24 | G24: 4PzS500 | H24: 388KG | J24: a | K24: =VLOOKUP(G24,'CPYData Validation'!G:H,2,FALSE)*Table31018122324[[#This Row],[If Complete Battery - Voltage]]/2 -> #N/A | L24: =Table41119123325[[#This Row],[Pb Content Kg]]*K1/1000 -> #N/A
A25: 10 | B25: LG61/769 | C25: L005748 | D25: ENERSYS | F25: 48 | G25: 5PZS775 | H25: 1170KG | J25: a | K25: =VLOOKUP(G25,'CPYData Validation'!G:H,2,FALSE)*Table31018122324[[#This Row],[If Complete Battery - Voltage]]/2 -> #N/A | L25: =Table41119123325[[#This Row],[Pb Content Kg]]*K1/1000 -> #N/A
H26: COLLECT 3X STILLAGES OF 12V BATTs, CENTRAL/UNIT2 | J26: a | K26: 1218 | L26: 353.22
A27: 11 | B27: LG61/770 | C27: L005747 | D27: GNB | F27: 48 | G27: 5PzS775 | H27: 1170KG | J27: a | K27: =VLOOKUP(G27,'CPYData Validation'!G:H,2,FALSE)*Table31018122324[[#This Row],[If Complete Battery - Voltage]]/2 -> #N/A | L27: =Table41119123325[[#This Row],[Pb Content Kg]]*K1/1000 -> #N/A
A28: 12 | B28: LG61/771 | C28: L005741 | D28: GNB | F28: 48 | G28: 5PzS775 | H28: 1170KG | J28: a | K28: =VLOOKUP(G28,'CPYData Validation'!G:H,2,FALSE)*Table31018122324[[#This Row],[If Complete Battery - Voltage]]/2 -> #N/A | L28: =Table41119123325[[#This Row],[Pb Content Kg]]*K1/1000 -> #N/A
A29: 13 | B29: LG61/772 | C29: LB01422603 | D29: GNB | F29: 48 | G29: 5PzS775 | H29: 1170KG | J29: r | M29: Not available to load
A30: 14 | B30: LG61/773 | C30: L005734 | D30: GNB | F30: 48 | G30: 5PzS775 | H30: 1170KG | J30: r | M30: Not available to load
A31: 15 | B31: LG61/774 | C31: L005722 | D31: GNB | F31: 48 | G31: 5PzS775 | H31: 1170KG | J31: a | K31: =VLOOKUP(G31,'CPYData Validation'!G:H,2,FALSE)*Table31018122324[[#This Row],[If Complete Battery - Voltage]]/2 -> #N/A | L31: =Table41119123325[[#This Row],[Pb Content Kg]]*K1/1000 -> #N/A
A32: 16 | B32: LG61/775 | C32: L005746 | D32: GNB | F32: 24 | G32: 4PzS500 | H32: 388KG | J32: a | K32: =VLOOKUP(G32,'CPYData Validation'!G:H,2,FALSE)*Table31018122324[[#This Row],[If Complete Battery - Voltage]]/2 -> #N/A | L32: =Table41119123325[[#This Row],[Pb Content Kg]]*K1/1000 -> #N/A
A33: 17 | B33: LG61/776 | C33: L005729 | D33: GNB | F33: 24 | G33: 4PzS620 | H33: 465KG | J33: a | K33: =VLOOKUP(G33,'CPYData Validation'!G:H,2,FALSE)*Table31018122324[[#This Row],[If Complete Battery - Voltage]]/2 -> #N/A | L33: =Table41119123325[[#This Row],[Pb Content Kg]]*K1/1000 -> #N/A
A34: 17 | B34: LG61/777 | C34: L005730 | D34: GNB | F34: 24 | G34: 4PzS620 | H34: 465KG | J34: a | K34: =VLOOKUP(G34,'CPYData Validation'!G:H,2,FALSE)*Table31018122324[[#This Row],[If Complete Battery - Voltage]]/2 -> #N/A | L34: =Table41119123325[[#This Row],[Pb Content Kg]]*K1/1000 -> #N/A
A35: 17 | B35: LG61/778 | C35: L005725 | D35: GNB | F35: 24 | G35: 4PzS620 | H35: 465KG | J35: a | K35: =VLOOKUP(G35,'CPYData Validation'!G:H,2,FALSE)*Table31018122324[[#This Row],[If Complete Battery - Voltage]]/2 -> #N/A | L35: =Table41119123325[[#This Row],[Pb Content Kg]]*K1/1000 -> #N/A
A36: 18 | B36: LG61/779 | C36: L005718 | D36: GNB | F36: 48 | G36: 4PzS500 | H36: 720KG | J36: a | K36: =VLOOKUP(G36,'CPYData Validation'!G:H,2,FALSE)*Table31018122324[[#This Row],[If Complete Battery - Voltage]]/2 -> #N/A | L36: =Table41119123325[[#This Row],[Pb Content Kg]]*K1/1000 -> #N/A
A37: 19 | B37: LG61/780 | C37: L005719 | D37: GNB | F37: 24 | G37: 4PzS500 | H37: 388KG | J37: r | M37: Not available to load
A38: 19 | B38: LG61/781 | C38: L005720 | D38: GNB | F38: 24 | G38: 4PzS620 | H38: 465KG | J38: r | M38: Not available to load
A39: 19 | B39: LG61/782 | C39: L005721 | D39: GNB | F39: 24 | G39: 4PzS500 | H39: 388KG | J39: r | M39: Not available to load
A40: #1 | B40: S830 | C40: N/A | D40: N/A | F40: 24 | G40: 3PzS375 | J40: a | K40: =VLOOKUP(G40,'CPYData Validation'!G:H,2,FALSE)*Table31018122324[[#This Row],[If Complete Battery - Voltage]]/2 -> #N/A | L40: =Table41119123325[[#This Row],[Pb Content Kg]]*K1/1000 -> #N/A | M40: Additional pallet collected
...

Sheet CPYC02261163
A1: #VALUE! | C1: Redundant Battery Collection Note Job No. 02261163 | G1: collections@itinium.co.uk | H1: #VALUE! | K1: 100 | M1: #VALUE!
A2: Collection Date: | B2: 46085 | D2: Collection point: | E2: Still Materials Handling Ltd, Jacks Way, Hill Barton Business Park, Clyst St Mary, Exeter , EX5 1FG
A3: Pallet No. | B3: Asset No. | C3: Battery Serial Number | D3: Manufacture | E3: If Loose Cells - Qty | F3: If Complete Battery - Voltage | G3: Type of Cells PZB/PZS/PZV/Blocs etc. | H3: Notes | I3: →Intinium to Complete← | J3: Confirmation of receipt | K3: Pb Content Kg | L3: £ Value | M3: Notes
A4: PALLET 1 | B4: N/A | C4: N/A | D4: N/A | F4: 48 | G4: 6PZS930 | J4: a | K4: =VLOOKUP(G4,'CPYData Validation'!G:H,2,FALSE)*Table31018122346[[#This Row],[If Complete Battery - Voltage]]/2 -> #N/A | L4: =Table41119123347[[#This Row],[Pb Content Kg]]*K1/1000 -> #N/A
A5: PALLET 2 | B5: N/A | C5: N/A | D5: N/A | F5: 48 | G5: 6PZS930 | J5: a | K5: =VLOOKUP(G5,'CPYData Validation'!G:H,2,FALSE)*Table31018122346[[#This Row],[If Complete Battery - Voltage]]/2 -> #N/A | L5: =Table41119123347[[#This Row],[Pb Content Kg]]*K1/1000 -> #N/A
A6: PALLET 3 | B6: S003458 | C6: 101408447 | D6: GNB | F6: 80 | G6: 1620TCSM | J6: a | K6: =VLOOKUP(G6,'CPYData Validation'!G:H,2,FALSE)*Table31018122346[[#This Row],[If Complete Battery - Voltage]]/2 -> #N/A | L6: =Table41119123347[[#This Row],[Pb Content Kg]]*K1/1000 -> #N/A
A7: PALLET 4 | B7: S003459 | C7: 101408469 | D7: GNB | F7: 80 | G7: 1620TCSM | J7: a | K7: =VLOOKUP(G7,'CPYData Validation'!G:H,2,FALSE)*Table31018122346[[#This Row],[If Complete Battery - Voltage]]/2 -> #N/A | L7: =Table41119123347[[#This Row],[Pb Content Kg]]*K1/1000 -> #N/A
A8: PALLET 5 | B8: S003460 | C8: 101408461 | D8: GNB | F8: 80 | G8: 1620TCSM | J8: a | K8: =VLOOKUP(G8,'CPYData Validation'!G:H,2,FALSE)*Table31018122346[[#This Row],[If Complete Battery - Voltage]]/2 -> #N/A | L8: =Table41119123347[[#This Row],[Pb Content Kg]]*K1/1000 -> #N/A
A9: PALLET 6 | B9: S003461 | C9: 101408455 | D9: GNB | F9: 80 | G9: 1620TCSM | J9: a | K9: =VLOOKUP(G9,'CPYData Validation'!G:H,2,FALSE)*Table31018122346[[#This Row],[If Complete Battery - Voltage]]/2 -> #N/A | L9: =Table41119123347[[#This Row],[Pb Content Kg]]*K1/1000 -> #N/A
A10: PALLET 7 | B10: S003462 | C10: 101408427 | D10: GNB | F10: 80 | G10: 1620TCSM | J10: a | K10: =VLOOKUP(G10,'CPYData Validation'!G:H,2,FALSE)*Table31018122346[[#This Row],[If Complete Battery - Voltage]]/2 -> #N/A | L10: =Table41119123347[[#This Row],[Pb Content Kg]]*K1/1000 -> #N/A
A11: PALLET 8 | B11: S003463 | C11: P07346 | D11: TABI | F11: 80 | G11: 1620TCSM | J11: a | K11: =VLOOKUP(G11,'CPYData Validation'!G:H,2,FALSE)*Table31018122346[[#This Row],[If Complete Battery - Voltage]]/2 -> #N/A | L11: =Table41119123347[[#This Row],[Pb Content Kg]]*K1/1000 -> #N/A
A12: PALLET 9 | B12: S003464 | C12: 100654494 | D12: GNB | F12: 80 | G12: 6PZS840 | J12: a | K12: =VLOOKUP(G12,'CPYData Validation'!G:H,2,FALSE)*Table31018122346[[#This Row],[If Complete Battery - Voltage]]/2 -> #N/A | L12: =Table41119123347[[#This Row],[Pb Content Kg]]*K1/1000 -> #N/A
A13: PALLET 10 | B13: S003465 | C13: N21315 | D13: TABI | F13: 48 | G13: 5PZS775 | J13: a | K13: =VLOOKUP(G13,'CPYData Validation'!G:H,2,FALSE)*Table31018122346[[#This Row],[If Complete Battery - Voltage]]/2 -> #N/A | L13: =Table41119123347[[#This Row],[Pb Content Kg]]*K1/1000 -> #N/A
A14: PALLET 11 | B14: S003466 | C14: N/A | D14: N/A | F14: 48 | G14: 5PZS775 | J14: a | K14: =VLOOKUP(G14,'CPYData Validation'!G:H,2,FALSE)*Table31018122346[[#This Row],[If Complete Battery - Voltage]]/2 -> #N/A | L14: =Table41119123347[[#This Row],[Pb Content Kg]]*K1/1000 -> #N/A
D34: This document is the confirmation and agreement for Itinium to remove the above redundant batteries for further inspection.
A35: Collection Driver | G35: Site Contact Name
A36: Date | G36: Date
A38: Signature | G38: Signature
J39: Transport | M39: 0
J40: Total Invoice Value | M40: =SUM(L4:L39)-M39 -> #N/A
J41: Invoice Number

Sheet CPY03261165
A1: #VALUE! | C1: Redundant Battery Collection Note Job No.03261165 | G1: collections@itinium.co.uk | H1: #VALUE! | K1: 100 | M1: #VALUE!
A2: Collection Date: | B2: 46099 | D2: Collection point: | E2: Linde MH UK Ltd, Pioneer Way, Castleford, West Yorkshire, WF10 5QU
A3: Pallet No. | B3: Asset No. | C3: Battery Serial Number | D3: Manufacture | E3: If Loose Cells - Qty | F3: If Complete Battery - Voltage | G3: Type of Cells PZB/PZS/PZV/Blocs etc. | H3: Notes | I3: →Intinium to Complete← | J3: Confirmation of receipt | K3: Pb Content Kg | L3: £ Value | M3: Notes
A4: 1 | B4: 201430841 | D4: GNB | F4: 48 | G4: 6PzS480 | H4: approx 1290 kg | K4: =VLOOKUP(G4,'CPYData Validation'!G:H,2,FALSE)*Table31018122350[[#This Row],[If Complete Battery - Voltage]]/2 -> #N/A | L4: =Table41119123351[[#This Row],[Pb Content Kg]]*K1/1000 -> #N/A
A5: 2 | B5: 201445472 | D5: GNB | F5: 48 | G5: 6PzS840 | H5: approx 1290 kg | K5: =VLOOKUP(G5,'CPYData Validation'!G:H,2,FALSE)*Table31018122350[[#This Row],[If Complete Battery - Voltage]]/2 -> #N/A | L5: =Table41119123351[[#This Row],[Pb Content Kg]]*K1/1000 -> #N/A
A6: 3 | B6: LB01421717 | D6: GNB | F6: 48 | G6: 6PzS840 | H6: approx 1290 kg | K6: =VLOOKUP(G6,'CPYData Validation'!G:H,2,FALSE)*Table31018122350[[#This Row],[If Complete Battery - Voltage]]/2 -> #N/A | L6: =Table41119123351[[#This Row],[Pb Content Kg]]*K1/1000 -> #N/A
A7: 4 | B7: LB01489912 | D7: GNB | F7: 48 | G7: 6PzS930 | H7: approx 1330 kg | K7: =VLOOKUP(G7,'CPYData Validation'!G:H,2,FALSE)*Table31018122350[[#This Row],[If Complete Battery - Voltage]]/2 -> #N/A | L7: =Table41119123351[[#This Row],[Pb Content Kg]]*K1/1000 -> #N/A
A8: 5 | B8: 201445473 | D8: GNB | F8: 48 | G8: 6PzS840 | H8: approx 1290 kg | K8: =VLOOKUP(G8,'CPYData Validation'!G:H,2,FALSE)*Table31018122350[[#This Row],[If Complete Battery - Voltage]]/2 -> #N/A | L8: =Table41119123351[[#This Row],[Pb Content Kg]]*K1/1000 -> #N/A
A9: 6 | B9: 201445376 | D9: GNB | F9: 48 | G9: 6PzS840 | H9: approx 1290 kg | K9: =VLOOKUP(G9,'CPYData Validation'!G:H,2,FALSE)*Table31018122350[[#This Row],[If Complete Battery - Voltage]]/2 -> #N/A | L9: =Table41119123351[[#This Row],[Pb Content Kg]]*K1/1000 -> #N/A
A10: 7 | B10: 201430786 | D10: GNB | F10: 48 | G10: 6PzS840 | H10: approx 1290 kg | K10: =VLOOKUP(G10,'CPYData Validation'!G:H,2,FALSE)*Table31018122350[[#This Row],[If Complete Battery - Voltage]]/2 -> #N/A | L10: =Table41119123351[[#This Row],[Pb Content Kg]]*K1/1000 -> #N/A
A11: 8 | B11: 201445480 | D11: GNB | F11: 48 | G11: 6PzS840 | H11: approx 1290 kg | K11: =VLOOKUP(G11,'CPYData Validation'!G:H,2,FALSE)*Table31018122350[[#This Row],[If Complete Battery - Voltage]]/2 -> #N/A | L11: =Table41119123351[[#This Row],[Pb Content Kg]]*K1/1000 -> #N/A
A12: 9 | D12: GNB | E12: 21 | G12: 6PzS840 | H12: 21 x 6PZS 840 and 3 x 6 PZS930 scrap cells in tray, approx 1300kg | K12: =VLOOKUP(G12,'CPYData Validation'!G:H,2,FALSE)*Table31018122350[[#This Row],[If Complete Battery - Voltage]]/2 -> #N/A | L12: =Table41119123351[[#This Row],[Pb Content Kg]]*K1/1000 -> #N/A
A13: 9 | D13: GNB | E13: 3 | G13: 6PzS930 | K13: =VLOOKUP(G13,'CPYData Validation'!G:H,2,FALSE)*Table31018122350[[#This Row],[If Complete Battery - Voltage]]/2 -> #N/A | L13: =Table41119123351[[#This Row],[Pb Content Kg]]*K1/1000 -> #N/A
A14: 10 | B14: 201430784 | D14: GNB | F14: 48 | G14: 6PzS840 | H14: approx 1290 kg | K14: =VLOOKUP(G14,'CPYData Validation'!G:H,2,FALSE)*Table31018122350[[#This Row],[If Complete Battery - Voltage]]/2 -> #N/A | L14: =Table41119123351[[#This Row],[Pb Content Kg]]*K1/1000 -> #N/A
A15: 11 | B15: 201445457 | D15: GNB | F15: 48 | G15: 6PzS840 | H15: approx 1290 kg | K15: =VLOOKUP(G15,'CPYData Validation'!G:H,2,FALSE)*Table31018122350[[#This Row],[If Complete Battery - Voltage]]/2 -> #N/A | L15: =Table41119123351[[#This Row],[Pb Content Kg]]*K1/1000 -> #N/A
A16: 12 | B16: 201430855 | D16: GNB | F16: 48 | G16: 6PzS840 | H16: approx 1290 kg | K16: =VLOOKUP(G16,'CPYData Validation'!G:H,2,FALSE)*Table31018122350[[#This Row],[If Complete Battery - Voltage]]/2 -> #N/A | L16: =Table41119123351[[#This Row],[Pb Content Kg]]*K1/1000 -> #N/A
A17: 13 | B17: 201430856 | D17: GNB | F17: 48 | G17: 6PzS840 | H17: approx 1290 kg | K17: =VLOOKUP(G17,'CPYData Validation'!G:H,2,FALSE)*Table31018122350[[#This Row],[If Complete Battery - Voltage]]/2 -> #N/A | L17: =Table41119123351[[#This Row],[Pb Content Kg]]*K1/1000 -> #N/A
A18: 14 | B18: 201430857 | D18: GNB | F18: 48 | G18: 6PzS840 | H18: approx 1290 kg | K18: =VLOOKUP(G18,'CPYData Validation'!G:H,2,FALSE)*Table31018122350[[#This Row],[If Complete Battery - Voltage]]/2 -> #N/A | L18: =Table41119123351[[#This Row],[Pb Content Kg]]*K1/1000 -> #N/A
A19: 15 | B19: 201430844 | D19: GNB | F19: 48 | G19: 6PzS840 | H19: approx 1290 kg | K19: =VLOOKUP(G19,'CPYData Validation'!G:H,2,FALSE)*Table31018122350[[#This Row],[If Complete Battery - Voltage]]/2 -> #N/A | L19: =Table41119123351[[#This Row],[Pb Content Kg]]*K1/1000 -> #N/A
A20: 16 | B20: 201445468 | D20: GNB | F20: 48 | G20: 6PzS840 | H20: approx 1290 kg | K20: =VLOOKUP(G20,'CPYData Validation'!G:H,2,FALSE)*Table31018122350[[#This Row],[If Complete Battery - Voltage]]/2 -> #N/A | L20: =Table41119123351[[#This Row],[Pb Content Kg]]*K1/1000 -> #N/A
A21: 17 | B21: 201430847 | D21: GNB | F21: 48 | G21: 6PzS840 | H21: approx 1290 kg | K21: =VLOOKUP(G21,'CPYData Validation'!G:H,2,FALSE)*Table31018122350[[#This Row],[If Complete Battery - Voltage]]/2 -> #N/A | L21: =Table41119123351[[#This Row],[Pb Content Kg]]*K1/1000 -> #N/A
A22: 18 | B22: 201430840 | D22: GNB | F22: 48 | G22: 6PzS840 | H22: approx 1290 kg | K22: =VLOOKUP(G22,'CPYData Validation'!G:H,2,FALSE)*Table31018122350[[#This Row],[If Complete Battery - Voltage]]/2 -> #N/A | L22: =Table41119123351[[#This Row],[Pb Content Kg]]*K1/1000 -> #N/A
A23: 19 | B23: 101484446 | D23: GNB | F23: 80 | G23: 6PzS840 | H23: approx 1900 kg | K23: =VLOOKUP(G23,'CPYData Validation'!G:H,2,FALSE)*Table31018122350[[#This Row],[If Complete Battery - Voltage]]/2 -> #N/A | L23: =Table41119123351[[#This Row],[Pb Content Kg]]*K1/1000 -> #N/A
A24: 20 | B24: 101484440 | D24: GNB | F24: 80 | G24: 6PzS840 | H24: approx 1900 kg | K24: =VLOOKUP(G24,'CPYData Validation'!G:H,2,FALSE)*Table31018122350[[#This Row],[If Complete Battery - Voltage]]/2 -> #N/A | L24: =Table41119123351[[#This Row],[Pb Content Kg]]*K1/1000 -> #N/A
D34: This document is the confirmation and agreement for Itinium to remove the above redundant batteries for further inspection.
A35: Collection Driver | G35: Site Contact Name
A36: Date | G36: Date
A38: Signature | G38: Signature
J39: Transport | M39: 0
J40: Total Invoice Value | M40: =SUM(L4:L39)-M39 -> #N/A
J41: Invoice Number

Sheet Sheet1
